[2022-11-17T11:27:42.777+0000] {taskinstance.py:1165} INFO - Dependencies all met for <TaskInstance: first_python_dag_v4.greet manual__2022-11-17T11:25:39.590997+00:00 [queued]>
[2022-11-17T11:27:42.796+0000] {taskinstance.py:1165} INFO - Dependencies all met for <TaskInstance: first_python_dag_v4.greet manual__2022-11-17T11:25:39.590997+00:00 [queued]>
[2022-11-17T11:27:42.796+0000] {taskinstance.py:1362} INFO - 
--------------------------------------------------------------------------------
[2022-11-17T11:27:42.797+0000] {taskinstance.py:1363} INFO - Starting attempt 2 of 6
[2022-11-17T11:27:42.797+0000] {taskinstance.py:1364} INFO - 
--------------------------------------------------------------------------------
[2022-11-17T11:27:42.838+0000] {taskinstance.py:1383} INFO - Executing <Task(PythonOperator): greet> on 2022-11-17 11:25:39.590997+00:00
[2022-11-17T11:27:42.848+0000] {standard_task_runner.py:55} INFO - Started process 9778 to run task
[2022-11-17T11:27:42.853+0000] {standard_task_runner.py:82} INFO - Running: ['***', 'tasks', 'run', 'first_python_dag_v4', 'greet', 'manual__2022-11-17T11:25:39.590997+00:00', '--job-id', '9', '--raw', '--subdir', 'DAGS_FOLDER/python_dag.py', '--cfg-path', '/tmp/tmpxgi08aoh']
[2022-11-17T11:27:42.857+0000] {standard_task_runner.py:83} INFO - Job 9: Subtask greet
[2022-11-17T11:27:42.970+0000] {task_command.py:376} INFO - Running <TaskInstance: first_python_dag_v4.greet manual__2022-11-17T11:25:39.590997+00:00 [running]> on host 40055b85ab48
[2022-11-17T11:27:43.089+0000] {taskinstance.py:1592} INFO - Exporting the following env vars:
AIRFLOW_CTX_DAG_OWNER=coder2j
AIRFLOW_CTX_DAG_ID=first_python_dag_v4
AIRFLOW_CTX_TASK_ID=greet
AIRFLOW_CTX_EXECUTION_DATE=2022-11-17T11:25:39.590997+00:00
AIRFLOW_CTX_TRY_NUMBER=2
AIRFLOW_CTX_DAG_RUN_ID=manual__2022-11-17T11:25:39.590997+00:00
[2022-11-17T11:27:43.090+0000] {taskinstance.py:1851} ERROR - Task failed with exception
Traceback (most recent call last):
  File "/home/airflow/.local/lib/python3.7/site-packages/airflow/operators/python.py", line 175, in execute
    return_value = self.execute_callable()
  File "/home/airflow/.local/lib/python3.7/site-packages/airflow/operators/python.py", line 193, in execute_callable
    return self.python_callable(*self.op_args, **self.op_kwargs)
  File "/opt/airflow/dags/python_dag.py", line 13, in greet
    name = ti.xcoms_pull(task_ids='get_name')
AttributeError: 'TaskInstance' object has no attribute 'xcoms_pull'
[2022-11-17T11:27:43.101+0000] {taskinstance.py:1406} INFO - Marking task as UP_FOR_RETRY. dag_id=first_python_dag_v4, task_id=greet, execution_date=20221117T112539, start_date=20221117T112742, end_date=20221117T112743
[2022-11-17T11:27:43.119+0000] {standard_task_runner.py:105} ERROR - Failed to execute job 9 for task greet ('TaskInstance' object has no attribute 'xcoms_pull'; 9778)
[2022-11-17T11:27:43.144+0000] {local_task_job.py:159} INFO - Task exited with return code 1
[2022-11-17T11:27:43.203+0000] {taskinstance.py:2623} INFO - 0 downstream tasks scheduled from follow-on schedule check
